[2024-03-25T14:13:01.522+0000] {scheduler_job_runner.py:781} ERROR - Executor reports task instance <TaskInstance: data_pipeline.extract_product_id scheduled__2024-03-19T00:00:00+00:00 [queued]> finished (failed) although the task says it's queued. (Info: None) Was the task killed externally?
